<?xml version="1.0" ?>
<!-- =================================================================================== -->
<!-- |    This document was autogenerated by xacro from lara.xacro                     | -->
<!-- |    EDITING THIS FILE BY HAND IS NOT RECOMMENDED                                 | -->
<!-- =================================================================================== -->
<robot name="lara">
  <link name="chassis">
    <visual>
      <geometry>
        <mesh filename="package://lara_model/objs/Chassis.obj"/>
      </geometry>
    </visual>
    <collision>
      <geometry>
        <mesh filename="package://lara_model/objs/Chassis.obj"/>
      </geometry>
    </collision>
  </link>
  <link name="link_1">
    <visual>
      <geometry>
        <mesh filename="package://lara_model/objs/Link1.obj"/>
      </geometry>
    </visual>
    <collision>
      <geometry>
        <mesh filename="package://lara_model/objs/Link1.obj"/>
      </geometry>
    </collision>
  </link>
  <joint name="chassis_to_link_1" type="revolute">
    <axis xyz="0 0 1"/>
    <limit effort="1000.0" lower="-1.5707963267948966" upper="1.5707963267948966" velocity="0.5"/>
    <parent link="chassis"/>
    <child link="link_1"/>
    <origin rpy="0 0 0" xyz="-0.0000005953 -0.05506373 0.36944"/>
  </joint>
  <link name="link_2">
    <visual>
      <geometry>
        <mesh filename="package://lara_model/objs/Link2.obj"/>
      </geometry>
    </visual>
    <collision>
      <geometry>
        <mesh filename="package://lara_model/objs/Link2.obj"/>
      </geometry>
    </collision>
  </link>
  <joint name="link_1_to_link_2" type="revolute">
    <axis xyz="1 0 0"/>
    <limit effort="1000.0" lower="-1.5707963267948966" upper="1.5707963267948966" velocity="0.5"/>
    <parent link="link_1"/>
    <child link="link_2"/>
    <origin rpy="0 0 0" xyz="0 0.145 0"/>
  </joint>
  <link name="link_3">
    <visual>
      <geometry>
        <mesh filename="package://lara_model/objs/Link3.obj"/>
      </geometry>
    </visual>
    <collision>
      <geometry>
        <mesh filename="package://lara_model/objs/Link3.obj"/>
      </geometry>
    </collision>
  </link>
  <joint name="link_2_to_link_3" type="revolute">
    <axis xyz="1 0 0"/>
    <limit effort="1000.0" lower="-1.5707963267948966" upper="1.5707963267948966" velocity="0.5"/>
    <parent link="link_2"/>
    <child link="link_3"/>
    <origin rpy="0 0 0" xyz="0.0068396853 0.27 0"/>
  </joint>
  <link name="link_4">
    <visual>
      <geometry>
        <mesh filename="package://lara_model/objs/Link4.obj"/>
      </geometry>
    </visual>
    <collision>
      <geometry>
        <mesh filename="package://lara_model/objs/Link4.obj"/>
      </geometry>
    </collision>
  </link>
  <joint name="link_3_to_link_4" type="revolute">
    <axis xyz="0 1 0"/>
    <limit effort="1000.0" lower="-1.5707963267948966" upper="1.5707963267948966" velocity="0.5"/>
    <parent link="link_3"/>
    <child link="link_4"/>
    <origin rpy="0 0 0" xyz="0 0 0"/>
  </joint>
  <link name="link_5">
    <visual>
      <geometry>
        <mesh filename="package://lara_model/objs/Link5.obj"/>
      </geometry>
    </visual>
    <collision>
      <geometry>
        <mesh filename="package://lara_model/objs/Link5.obj"/>
      </geometry>
    </collision>
  </link>
  <joint name="link_4_to_link_5" type="revolute">
    <axis xyz="1 0 0"/>
    <limit effort="1000.0" lower="-1.5707963267948966" upper="1.5707963267948966" velocity="0.5"/>
    <parent link="link_4"/>
    <child link="link_5"/>
    <origin rpy="0 0 0" xyz="0 0 0"/>
  </joint>
  <link name="finger_r">
    <visual>
      <geometry>
        <mesh filename="package://lara_model/objs/FingerR.obj"/>
      </geometry>
    </visual>
    <collision>
      <geometry>
        <mesh filename="package://lara_model/objs/FingerR.obj"/>
      </geometry>
    </collision>
  </link>
  <joint name="link_5_to_finger_r" type="revolute">
    <axis xyz="0 0 1"/>
    <limit effort="1000.0" lower="-1.5707963267948966" upper="1.5707963267948966" velocity="0.5"/>
    <parent link="link_5"/>
    <child link="finger_r"/>
    <origin rpy="0 0 0" xyz="0.03284967 0.05965715 0.0045"/>
  </joint>
  <link name="finger_l">
    <visual>
      <geometry>
        <mesh filename="package://lara_model/objs/FingerL.obj"/>
      </geometry>
    </visual>
    <collision>
      <geometry>
        <mesh filename="package://lara_model/objs/FingerL.obj"/>
      </geometry>
    </collision>
  </link>
  <joint name="link_5_to_finger_l" type="revolute">
    <axis xyz="0 0 1"/>
    <limit effort="1000.0" lower="-1.5707963267948966" upper="1.5707963267948966" velocity="0.5"/>
    <parent link="link_5"/>
    <child link="finger_l"/>
    <origin rpy="0 0 0" xyz="-0.03715033 0.05965715 0.0045"/>
  </joint>
</robot>
